Traceback (most recent call last):
  File "c:\users\peter\appdata\local\programs\python\python37-32\lib\site-packages\jupyter_cache\executors\utils.py", line 64, in single_nb_execution
    **kwargs,
  File "c:\users\peter\appdata\local\programs\python\python37-32\lib\site-packages\nbclient\client.py", line 1305, in execute
    return NotebookClient(nb=nb, resources=resources, km=km, **kwargs).execute()
  File "c:\users\peter\appdata\local\programs\python\python37-32\lib\site-packages\jupyter_core\utils\__init__.py", line 98, in wrapped
    return loop.run_until_complete(inner)
  File "c:\users\peter\appdata\local\programs\python\python37-32\lib\asyncio\base_events.py", line 587, in run_until_complete
    return future.result()
  File "c:\users\peter\appdata\local\programs\python\python37-32\lib\site-packages\nbclient\client.py", line 706, in async_execute
    cell, index, execution_count=self.code_cells_executed + 1
  File "c:\users\peter\appdata\local\programs\python\python37-32\lib\site-packages\nbclient\client.py", line 1058, in async_execute_cell
    await self._check_raise_for_error(cell, cell_index, exec_reply)
  File "c:\users\peter\appdata\local\programs\python\python37-32\lib\site-packages\nbclient\client.py", line 914, in _check_raise_for_error
    raise CellExecutionError.from_cell_and_msg(cell, exec_reply_content)
nbclient.exceptions.CellExecutionError: An error occurred while executing the following cell:
------------------
import numpy as np
import matplotlib.pyplot as plt
from myst_nb import glue

def moving_average(x, k):
    n = len(x)
    y = np.zeros(n)

    for i in range(0, n):
        y[i] = np.average(x[max(i-k, 0):min(i+k+1, n)])
    
    return y

pressure_data = [1018.3, 1018.3, 1015.7, 1014.3, 1011.8, 1011.4, 1015.5, 1016.0, 1016.9, 1016.8, 1016.4, 1017.5, 1018.8, 1018.1, 1017.1, 1018.4, 1022.0, 1022.8, 1021.8, 1020.5, 1021.0, 1019.8, 1018.9, 1018.4, 1017.8, 1018.1, 1019.6, 1017.4, 1015.8, 1015.5, 1017.5, 1018.9, 1017.7, 1014.4, 1014.2, 1016.0, 1016.1, 1015.6, 1016.4, 1015.7, 1016.6, 1019.6, 1021.6, 1021.4, 1020.6, 1017.6, 1016.5, 1016.2, 1013.0, 1005.4, 1007.4, 1012.2, 1015.2, 1016.1, 1014.3, 1012.4, 1014.2, 1013.1, 1012.9, 1012.1, 1010.6, 1010.0, 1010.5, 1010.3, 1007.4, 1008.9, 1007.4, 1006.9, 1009.8, 1014.8, 1014.9, 1016.6, 1014.1, 1011.1, 1010.7, 1009.8, 1011.9, 1012.6, 1011.8, 1009.8, 1008.9, 1010.6, 1009.9, 1010.2, 1009.5, 1009.0, 1007.1, 1007.1, 1007.5, 1005.0, 1004.2, 1004.2, 1007.2, 1005.0, 1002.9, 1007.4, 1010.4, 1010.6, 1008.6, 1006.2, 1005.9, 1006.8, 1004.6, 1002.4, 1003.2, 1004.4, 1003.1, 1000.9, 998.6, 999.9, 1001.6, 1002.1, 1004.1]

fig = plt.figure(figsize=(8, 4))
plt.plot(moving_average(pressure_data, 10), label="10 day")
plt.plot(moving_average(pressure_data, 5), label="5 day")
plt.plot(pressure_data, label="raw data", color="black")
plt.grid()
plt.xlabel("Day")
plt.ylabel("Pressure (mbar)")
plt.legend()

glue("moving_average", fig, display=False)

fig2 = plt.figure(figsize=(6, 3))
plt.plot(pressure_data, label="raw data", color="black")
plt.grid()
plt.xlabel("Day")
plt.ylabel("Pressure (mbar)")
glue("pressure", fig2, display=False)
------------------


[1;31m---------------------------------------------------------------------------[0m
[1;31mModuleNotFoundError[0m                       Traceback (most recent call last)
[1;32m~\AppData\Local\Temp\ipykernel_6320\1226458975.py[0m in [0;36m<module>[1;34m[0m
[1;32m----> 1[1;33m [1;32mimport[0m [0mnumpy[0m [1;32mas[0m [0mnp[0m[1;33m[0m[1;33m[0m[0m
[0m[0;32m      2[0m [1;32mimport[0m [0mmatplotlib[0m[1;33m.[0m[0mpyplot[0m [1;32mas[0m [0mplt[0m[1;33m[0m[1;33m[0m[0m
[0;32m      3[0m [1;32mfrom[0m [0mmyst_nb[0m [1;32mimport[0m [0mglue[0m[1;33m[0m[1;33m[0m[0m
[0;32m      4[0m [1;33m[0m[0m
[0;32m      5[0m [1;32mdef[0m [0mmoving_average[0m[1;33m([0m[0mx[0m[1;33m,[0m [0mk[0m[1;33m)[0m[1;33m:[0m[1;33m[0m[1;33m[0m[0m

[1;31mModuleNotFoundError[0m: No module named 'numpy'

