Traceback (most recent call last):
  File "c:\users\peter\appdata\local\programs\python\python37-32\lib\site-packages\jupyter_cache\executors\utils.py", line 64, in single_nb_execution
    **kwargs,
  File "c:\users\peter\appdata\local\programs\python\python37-32\lib\site-packages\nbclient\client.py", line 1305, in execute
    return NotebookClient(nb=nb, resources=resources, km=km, **kwargs).execute()
  File "c:\users\peter\appdata\local\programs\python\python37-32\lib\site-packages\jupyter_core\utils\__init__.py", line 98, in wrapped
    return loop.run_until_complete(inner)
  File "c:\users\peter\appdata\local\programs\python\python37-32\lib\asyncio\base_events.py", line 587, in run_until_complete
    return future.result()
  File "c:\users\peter\appdata\local\programs\python\python37-32\lib\site-packages\nbclient\client.py", line 706, in async_execute
    cell, index, execution_count=self.code_cells_executed + 1
  File "c:\users\peter\appdata\local\programs\python\python37-32\lib\site-packages\nbclient\client.py", line 1058, in async_execute_cell
    await self._check_raise_for_error(cell, cell_index, exec_reply)
  File "c:\users\peter\appdata\local\programs\python\python37-32\lib\site-packages\nbclient\client.py", line 914, in _check_raise_for_error
    raise CellExecutionError.from_cell_and_msg(cell, exec_reply_content)
nbclient.exceptions.CellExecutionError: An error occurred while executing the following cell:
------------------
import numpy as np
import matplotlib.pyplot as plt

collatz_numbers = np.zeros(100)

for i in range(100):
    collatz_numbers[i] = collatz_number(i + 1)

# remember to plot the collatz numbers against 1-100, not 0-99
plt.figure(figsize=(4,4))
plt.plot(np.linspace(1, 100, 100), collatz_numbers)
plt.title('First 100 Collatz Numbers')
plt.xlabel('n')
plt.ylabel('Collatz Number')
------------------


[1;31m---------------------------------------------------------------------------[0m
[1;31mModuleNotFoundError[0m                       Traceback (most recent call last)
[1;32m~\AppData\Local\Temp\ipykernel_16544\3394894053.py[0m in [0;36m<module>[1;34m[0m
[1;32m----> 1[1;33m [1;32mimport[0m [0mnumpy[0m [1;32mas[0m [0mnp[0m[1;33m[0m[1;33m[0m[0m
[0m[0;32m      2[0m [1;32mimport[0m [0mmatplotlib[0m[1;33m.[0m[0mpyplot[0m [1;32mas[0m [0mplt[0m[1;33m[0m[1;33m[0m[0m
[0;32m      3[0m [1;33m[0m[0m
[0;32m      4[0m [0mcollatz_numbers[0m [1;33m=[0m [0mnp[0m[1;33m.[0m[0mzeros[0m[1;33m([0m[1;36m100[0m[1;33m)[0m[1;33m[0m[1;33m[0m[0m
[0;32m      5[0m [1;33m[0m[0m

[1;31mModuleNotFoundError[0m: No module named 'numpy'

